# Конструкция try...catch

Попытается выполнить блок кода в try, и если там упадет ошибка, выполнит блок catch.
Есть также блок finally, который выпонится в любом случае.

 **Конструкция служит для обработки ошибок**. Если во время выполнения кода падает ошибка, выполнение скрипта останавливается. Конструкция try...catch позволяет обработать ошибку и продолжить выполнение скрипта.

 ![image](https://github.com/AlinaLaniuk/interview/assets/101401177/55be08c4-d89f-45db-900f-ef798380de0d)

 Порядок работы: 
 1. Выполнение кода блока try
 2. Если в блоке нет ошибок, catch не выполнится, try выолнится до конца.
 3. Если же в try падает ошибка на какой-то строчке, остаток блока выполнен не будет и мы сразу свалимся в выполнение блока catch.


Важно помнить, что конструкция обработает только ошибки корректного кода. То есть синтаксические обработаны не будут, потому что оин выкидывается еще на стадии парсинга. 
Таким образом, конструкция может обработать ошибки во время исполнения кода (например, не найдена какая-то переменная или мы пытаемся вызвать как функцию что-то, что не является функцией), а также исключения, выборшенные черех throw.

try...catch не имеет отношения к ассинхронности. 

![image](https://github.com/AlinaLaniuk/interview/assets/101401177/2f6c6839-3119-48e9-a2bd-88585d4ea34a)

Здесь мы отправили сеттаймаутом функцию браузеру, а вызов этой функции произойдет позже. Try...catch уже закончил выполнение, поэтому упадет ошибка.


Тонкости работы конструкции прямо сейчас не очень интересны. https://learn.javascript.ru/try-catch - здесь хорошо расписано, как работают все блоки.
Главное сейчас запомнить саму суть.
